Running external command line application(s). This may print messages to stdout and/or stderr.
The command(s) being run are below. These commands cannot be manually re-run as they will depend on temporary files that no longer exist.

Command: run_dada.R --input_directory /tmp/tmpei_zdtb9/forward --input_directory_reverse /tmp/tmpei_zdtb9/reverse --output_path /tmp/tmpei_zdtb9/output.tsv.biom --output_track /tmp/tmpei_zdtb9/track.tsv --filtered_directory /tmp/tmpei_zdtb9/filt_f --filtered_directory_reverse /tmp/tmpei_zdtb9/filt_r --truncation_length 249 --truncation_length_reverse 249 --trim_left 19 --trim_left_reverse 20 --max_expected_errors 2.0 --max_expected_errors_reverse 2.0 --truncation_quality_score 2 --min_overlap 12 --pooling_method independent --chimera_method consensus --min_parental_fold 1.0 --allow_one_off False --num_threads 14 --learn_min_reads 1000000

Warning message:
package ‘optparse’ was built under R version 4.2.3 
R version 4.2.2 (2022-10-31) 
Loading required package: Rcpp
DADA2: 1.26.0 / Rcpp: 1.0.11 / RcppParallel: 5.1.6 
2) Filtering The filter removed all reads: /tmp/tmpei_zdtb9/filt_f/SRR17012290_L001_R1_001.fastq.gz and /tmp/tmpei_zdtb9/filt_r/SRR17012290_L001_R2_001.fastq.gz not written.
x
Error: No reads passed the filter (was truncLen longer than the read length?)
Traceback (most recent call last):
  File "/home/liangtian/.conda/envs/qiime2-amplicon-2023.9/lib/python3.8/site-packages/q2_dada2/_denoise.py", line 326, in denoise_paired
    run_commands([cmd])
  File "/home/liangtian/.conda/envs/qiime2-amplicon-2023.9/lib/python3.8/site-packages/q2_dada2/_denoise.py", line 36, in run_commands
    subprocess.run(cmd, check=True)
  File "/home/liangtian/.conda/envs/qiime2-amplicon-2023.9/lib/python3.8/subprocess.py", line 516, in run
    raise CalledProcessError(retcode, process.args,
subprocess.CalledProcessError: Command '['run_dada.R', '--input_directory', '/tmp/tmpei_zdtb9/forward', '--input_directory_reverse', '/tmp/tmpei_zdtb9/reverse', '--output_path', '/tmp/tmpei_zdtb9/output.tsv.biom', '--output_track', '/tmp/tmpei_zdtb9/track.tsv', '--filtered_directory', '/tmp/tmpei_zdtb9/filt_f', '--filtered_directory_reverse', '/tmp/tmpei_zdtb9/filt_r', '--truncation_length', '249', '--truncation_length_reverse', '249', '--trim_left', '19', '--trim_left_reverse', '20', '--max_expected_errors', '2.0', '--max_expected_errors_reverse', '2.0', '--truncation_quality_score', '2', '--min_overlap', '12', '--pooling_method', 'independent', '--chimera_method', 'consensus', '--min_parental_fold', '1.0', '--allow_one_off', 'False', '--num_threads', '14', '--learn_min_reads', '1000000']' returned non-zero exit status 2.

During handling of the above exception, another exception occurred:

Traceback (most recent call last):
  File "/home/liangtian/.conda/envs/qiime2-amplicon-2023.9/lib/python3.8/site-packages/q2cli/commands.py", line 520, in __call__
    results = self._execute_action(
  File "/home/liangtian/.conda/envs/qiime2-amplicon-2023.9/lib/python3.8/site-packages/q2cli/commands.py", line 581, in _execute_action
    results = action(**arguments)
  File "<decorator-gen-73>", line 2, in denoise_paired
  File "/home/liangtian/.conda/envs/qiime2-amplicon-2023.9/lib/python3.8/site-packages/qiime2/sdk/action.py", line 342, in bound_callable
    outputs = self._callable_executor_(
  File "/home/liangtian/.conda/envs/qiime2-amplicon-2023.9/lib/python3.8/site-packages/qiime2/sdk/action.py", line 566, in _callable_executor_
    output_views = self._callable(**view_args)
  File "/home/liangtian/.conda/envs/qiime2-amplicon-2023.9/lib/python3.8/site-packages/q2_dada2/_denoise.py", line 329, in denoise_paired
    raise ValueError(
ValueError: No reads passed the filter. trunc_len_f (249) or trunc_len_r (249) may be individually longer than read lengths, or trunc_len_f + trunc_len_r may be shorter than the length of the amplicon + 12 nucleotides (the length of the overlap). Alternatively, other arguments (such as max_ee or trunc_q) may be preventing reads from passing the filter.

